Workbook

Sheet README
B2: German Credit Data (Statlog)
B3: Purpose: documentation for the dataset used in the statistics practice projects.
B5: Source
B6: UCI Machine Learning Repository, Statlog (German Credit Data), dataset 144. Donor: Prof. Hans Hofmann, Universität Hamburg (1994). License CC BY 4.0.
B7: https://archive.ics.uci.edu/dataset/144/statlog+german+credit+data
B8: Retrieved 2026-10-19 from a GitHub mirror of the original german.data file (jbrownlee/Datasets/german.csv); checked: 1,000 rows, 21 columns, 700 good / 300 bad, all codes valid per the UCI codebook.
B10: Sheets
B11: Data: 1,000 applicants, codes replaced with labels, plus a derived 0/1 'bad' column. Raw values untouched otherwise.
B12: Assumptions: observed counts and bad rates by checking status (question 1, step 2), with PASS/FAIL checks.
B13: Data_RawCodes: same rows with the original A11-style codes.
B14: Codebook: every variable, its type and the meaning of each code.
B16: Notes
... B20: The dataset's documented cost matrix rates classifying a bad applicant as good as 5x worse than the reverse.

Sheet Data
B2: Data: decoded labels (1,000 applicants)
B3: Purpose: analysis-ready data. One row per applicant; 'bad' = 1 for bad credit risk.
B4: applicant_id | C4: checking_status | D4: duration_months | E4: credit_history | F4: purpose | G4: credit_amount | H4: savings | I4: employment_since | J4: installment_rate_pct | K4: personal_status_sex | L4: other_debtors | M4: residence_since | N4: property | O4: age | P4: other_installment_plans | Q4: housing | R4: existing_credits | S4: job | T4: people_liable | U4: telephone | V4: foreign_worker | W4: class | X4: bad
B5: 1 | C5: < 0 DM | D5: 6 | E5: critical account / other credits elsewhere | F5: radio/television | G5: 1169 | H5: unknown / no savings account | I5: >= 7 years | J5: 4 | K5: male: single | L5: none | M5: 4 | N5: real estate | O5: 67 | P5: none | Q5: own | R5: 2 | S5: skilled employee / official | T5: 1 | U5: yes, registered in customer's name | V5: yes | W5: 1 | X5: 0
B6: 2 | C6: 0 to < 200 DM | D6: 48 | E6: existing credits paid back duly till now | F6: radio/television | G6: 5951 | H6: < 100 DM | I6: 1 to < 4 years | J6: 2 | K6: female: divorced/separated/married | L6: none | M6: 2 | N6: real estate | O6: 22 | P6: none | Q6: own | R6: 1 | S6: skilled employee / official | T6: 1 | U6: none | V6: yes | W6: 2 | X6: 1
B7: 3 | C7: no checking account | D7: 12 | E7: critical account / other credits elsewhere | F7: education | G7: 2096 | H7: < 100 DM | I7: 4 to < 7 years | J7: 2 | K7: male: single | L7: none | M7: 3 | N7: real estate | O7: 49 | P7: none | Q7: own | R7: 1 | S7: unskilled resident | T7: 2 | U7: none | V7: yes | W7: 1 | X7: 0
B8: 4 | C8: < 0 DM | D8: 42 | E8: existing credits paid back duly till now | F8: furniture/equipment | G8: 7882 | H8: < 100 DM | I8: 4 to < 7 years | J8: 2 | K8: male: single | L8: guarantor | M8: 4 | N8: building society savings / life insurance | O8: 45 | P8: none | Q8: for free | R8: 1 | S8: skilled employee / official | T8: 2 | U8: none | V8: yes | W8: 1 | X8: 0
B9: 5 | C9: < 0 DM | D9: 24 | E9: delay in paying off in the past | F9: car (new) | G9: 4870 | H9: < 100 DM | I9: 1 to < 4 years | J9: 3 | K9: male: single | L9: none | M9: 4 | N9: unknown / no property | O9: 53 | P9: none | Q9: for free | R9: 2 | S9: skilled employee / official | T9: 2 | U9: none | V9: yes | W9: 2 | X9: 1
B10: 6 | C10: no checking account | D10: 36 | E10: existing credits paid back duly till now | F10: education | G10: 9055 | H10: unknown / no savings account | I10: 1 to < 4 years | J10: 2 | K10: male: single | L10: none | M10: 4 | N10: unknown / no property | O10: 35 | P10: none | Q10: for free | R10: 1 | S10: unskilled resident | T10: 2 | U10: yes, registered in customer's name | V10: yes | W10: 1 | X10: 0
B11: 7 | C11: no checking account | D11: 24 | E11: existing credits paid back duly till now | F11: furniture/equipment | G11: 2835 | H11: 500 to < 1000 DM | I11: >= 7 years | J11: 3 | K11: male: single | L11: none | M11: 4 | N11: building society savings / life insurance | O11: 53 | P11: none | Q11: own | R11: 1 | S11: skilled employee / official | T11: 1 | U11: none | V11: yes | W11: 1 | X11: 0
B12: 8 | C12: 0 to < 200 DM | D12: 36 | E12: existing credits paid back duly till now | F12: car (used) | G12: 6948 | H12: < 100 DM | I12: 1 to < 4 years | J12: 2 | K12: male: single | L12: none | M12: 2 | N12: car or other | O12: 35 | P12: none | Q12: rent | R12: 1 | S12: management / self-employed / highly qualified | T12: 1 | U12: yes, registered in customer's name | V12: yes | W12: 1 | X12: 0
B13: 9 | C13: no checking account | D13: 12 | E13: existing credits paid back duly till now | F13: radio/television | G13: 3059 | H13: >= 1000 DM | I13: 4 to < 7 years | J13: 2 | K13: male: divorced/separated | L13: none | M13: 4 | N13: real estate | O13: 61 | P13: none | Q13: own | R13: 1 | S13: unskilled resident | T13: 1 | U13: none | V13: yes | W13: 1 | X13: 0
B14: 10 | C14: 0 to < 200 DM | D14: 30 | E14: critical account / other credits elsewhere | F14: car (new) | G14: 5234 | H14: < 100 DM | I14: unemployed | J14: 4 | K14: male: married/widowed | L14: none | M14: 2 | N14: car or other | O14: 28 | P14: none | Q14: own | R14: 2 | S14: management / self-employed / highly qualified | T14: 1 | U14: none | V14: yes | W14: 2 | X14: 1
B15: 11 | C15: 0 to < 200 DM | D15: 12 | E15: existing credits paid back duly till now | F15: car (new) | G15: 1295 | H15: < 100 DM | I15: < 1 year | J15: 3 | K15: female: divorced/separated/married | L15: none | M15: 1 | N15: car or other | O15: 25 | P15: none | Q15: rent | R15: 1 | S15: skilled employee / official | T15: 1 | U15: none | V15: yes | W15: 2 | X15: 1
B16: 12 | C16: < 0 DM | D16: 48 | E16: existing credits paid back duly till now | F16: business | G16: 4308 | H16: < 100 DM | I16: < 1 year | J16: 3 | K16: female: divorced/separated/married | L16: none | M16: 4 | N16: building society savings / life insurance | O16: 24 | P16: none | Q16: rent | R16: 1 | S16: skilled employee / official | T16: 1 | U16: none | V16: yes | W16: 2 | X16: 1
... B1004: 1000 | C1004: 0 to < 200 DM | D1004: 45 | E1004: critical account / other credits elsewhere | F1004: car (used) | G1004: 4576 | H1004: 100 to < 500 DM | I1004: unemployed | J1004: 3 | K1004: male: single | L1004: none | M1004: 4 | N1004: car or other | O1004: 27 | P1004: none | Q1004: own | R1004: 1 | S1004: skilled employee / official | T1004: 1 | U1004: none | V1004: yes | W1004: 1 | X1004: 0

Sheet Assumptions
B2: Work
B3: Ho: Checking account status is not associated with default.
B4: Ha: Checking account status is associated with default.
B6: Assumptions: checking status vs. default
B7: Purpose: observed counts and bad rates by checking-account status (Step 2: describe the data).
B8: checking_status | C8: good (bad=0) | D8: bad (bad=1) | E8: total | F8: bad_rate | G8: Notes
B9: < 0 DM | C9: =COUNTIFS(Data!$C$5:$C$1004,"="&$B9,Data!$X$5:$X$1004,0) -> 139 | D9: =COUNTIFS(Data!$C$5:$C$1004,"="&$B9,Data!$X$5:$X$1004,1) -> 135 | E9: =C9+D9 -> 274 | F9: =D9/E9 -> 0.49270073 | G9: COUNTIFS uses "="& so labels starting with < or >= are matched as text, not read as comparisons.
B10: 0 to < 200 DM | C10: =COUNTIFS(Data!$C$5:$C$1004,"="&$B10,Data!$X$5:$X$1004,0) -> 164 | D10: =COUNTIFS(Data!$C$5:$C$1004,"="&$B10,Data!$X$5:$X$1004,1) -> 105 | E10: =C10+D10 -> 269 | F10: =D10/E10 -> 0.39033457
B11: >= 200 DM or salary assignment | C11: =COUNTIFS(Data!$C$5:$C$1004,"="&$B11,Data!$X$5:$X$1004,0) -> 49 | D11: =COUNTIFS(Data!$C$5:$C$1004,"="&$B11,Data!$X$5:$X$1004,1) -> 14 | E11: =C11+D11 -> 63 | F11: =D11/E11 -> 0.22222222
B12: no checking account | C12: =COUNTIFS(Data!$C$5:$C$1004,"="&$B12,Data!$X$5:$X$1004,0) -> 348 | D12: =COUNTIFS(Data!$C$5:$C$1004,"="&$B12,Data!$X$5:$X$1004,1) -> 46 | E12: =C12+D12 -> 394 | F12: =D12/E12 -> 0.11675127 | G12: Bad rate = bad / total for the row. Overall bad rate is the benchmark for each group.
B13: Total | C13: =SUM(C9:C12) -> 700 | D13: =SUM(D9:D12) -> 300 | E13: =SUM(E9:E12) -> 1000 | F13: =D13/E13 -> 0.3
B15: Expected counts under H0 (independence)
B16: Expected = row total x column total / grand total, i.e. what we'd see if every group had the overall bad rate.
B17: checking_status | C17: expected good | D17: expected bad | E17: total
B18: =B9 -> < 0 DM | C18: =$E9*C$13/$E$13 -> 191.8 | D18: =$E9*D$13/$E$13 -> 82.2 | E18: =C18+D18 -> 274
B19: =B10 -> 0 to < 200 DM | C19: =$E10*C$13/$E$13 -> 188.3 | D19: =$E10*D$13/$E$13 -> 80.7 | E19: =C19+D19 -> 269
B20: =B11 -> >= 200 DM or salary assignment | C20: =$E11*C$13/$E$13 -> 44.1 | D20: =$E11*D$13/$E$13 -> 18.9 | E20: =C20+D20 -> 63
B21: =B12 -> no checking account | C21: =$E12*C$13/$E$13 -> 275.8 | D21: =$E12*D$13/$E$13 -> 118.2 | E21: =C21+D21 -> 394
B22: Total | C22: =SUM(C18:C21) -> 700 | D22: =SUM(D18:D21) -> 300 | E22: =SUM(E18:E21) -> 1000 | F22: Expected totals must equal observed totals (700 / 300 / 1,000).
B25: Assumption Testing
B26: Assumption | C26: How checked | D26: Value | E26: Decision | F26: Notes
B27: Expected count >= 5 in every cell | C27: MIN of expected table | D27: =MIN(C18:D21) -> 18.9 | E27: =IF(D27>=5,"Met","Not met") -> Met | F27: Chi-square relies on a large-sample approximation; small expected counts make the p-value unreliable.
B28: Share of cells with expected < 5 | C28: COUNTIF / 8 cells | D28: =COUNTIF(C18:D21,"<5")/COUNT(C18:D21) -> 0 | E28: =IF(D28<=0.2,"Met","Not met") -> Met | F28: Cochran's rule: no more than 20% of cells below 5, none below 1.
B29: Observed totals = expected totals | C29: Compare rows 10 and 28 | D29: =AND(C13=C22,D13=D22,E13=E22) -> TRUE | E29: =IF(D29,"Met","Not met") -> Met | F29: Sanity check on the expected-count formula.
B30: Independence of observations | C30: Judgment (cannot be tested from the data) | D30: One row per applicant | E30: Assumed met | F30: Each applicant is counted once and in one cell. It would fail if the same customer appeared on several loans.
B31: Categories mutually exclusive | C31: Judgment / data structure | D31: Each applicant has one status | E31: Met | F31: Every applicant falls in exactly one checking-status group and one outcome.
B33: Chi-Square Calculation
B34: checking_status | C34: good (bad=0) | D34: bad (bad=1)
B35: < 0 DM | C35: =(C9-C18)^2/C18 -> 14.535141 | D35: =(D9-D18)^2/D18 -> 33.915328
B36: 0 to < 200 DM | C36: =(C10-C19)^2/C19 -> 3.1359002 | D36: =(D10-D19)^2/D19 -> 7.3171004
B37: >= 200 DM or salary assignment | C37: =(C11-C20)^2/C20 -> 0.54444444 | D37: =(D11-D20)^2/D20 -> 1.2703704
B38: no checking account | C38: =(C12-C21)^2/C21 -> 18.900798 | D38: =(D12-D21)^2/D21 -> 44.101861
B41: Chi-Square | C41: =SUM(C35:D38) -> 123.72094
B42: df | C42: =(4-1)*(2-1) -> 3
B43: p-value | C43: =_xlfn.CHISQ.DIST.RT(C41, C42) -> 1.2189021e-26
B44: Cross-Check | C44: =_xlfn.CHISQ.TEST(C9:D12, C18:D21) -> 1.2189021e-26
B45: Critical Value at 0.05 | C45: =_xlfn.CHISQ.INV.RT(0.05,3) -> 7.8147279
B46: Cramer's V | C46: =SQRT(C41/(1000*(1))) -> 0.35173988
B49: Decision | C49: p < 0.05, so reject H0. Checking-account status is associated with default.
B50: Interpretation of Effect Size | C50: 0.35 is a medium association. Checking status clearly matters, but on its own it’s far from a perfect predictor of default. That fits what you’d expect from one variable in a credit model. Far fewer bad loans for no checkinga ccount than for the other categories.

Sheet Data_RawCodes
B2: Data_RawCodes: original UCI codes
B3: Purpose: original coded values, for checking against the UCI source.
B4: applicant_id | C4: checking_status | D4: duration_months | E4: credit_history | F4: purpose | G4: credit_amount | H4: savings | I4: employment_since | J4: installment_rate_pct | K4: personal_status_sex | L4: other_debtors | M4: residence_since | N4: property | O4: age | P4: other_installment_plans | Q4: housing | R4: existing_credits | S4: job | T4: people_liable | U4: telephone | V4: foreign_worker | W4: class
B5: 1 | C5: A11 | D5: 6 | E5: A34 | F5: A43 | G5: 1169 | H5: A65 | I5: A75 | J5: 4 | K5: A93 | L5: A101 | M5: 4 | N5: A121 | O5: 67 | P5: A143 | Q5: A152 | R5: 2 | S5: A173 | T5: 1 | U5: A192 | V5: A201 | W5: 1
B6: 2 | C6: A12 | D6: 48 | E6: A32 | F6: A43 | G6: 5951 | H6: A61 | I6: A73 | J6: 2 | K6: A92 | L6: A101 | M6: 2 | N6: A121 | O6: 22 | P6: A143 | Q6: A152 | R6: 1 | S6: A173 | T6: 1 | U6: A191 | V6: A201 | W6: 2
B7: 3 | C7: A14 | D7: 12 | E7: A34 | F7: A46 | G7: 2096 | H7: A61 | I7: A74 | J7: 2 | K7: A93 | L7: A101 | M7: 3 | N7: A121 | O7: 49 | P7: A143 | Q7: A152 | R7: 1 | S7: A172 | T7: 2 | U7: A191 | V7: A201 | W7: 1
B8: 4 | C8: A11 | D8: 42 | E8: A32 | F8: A42 | G8: 7882 | H8: A61 | I8: A74 | J8: 2 | K8: A93 | L8: A103 | M8: 4 | N8: A122 | O8: 45 | P8: A143 | Q8: A153 | R8: 1 | S8: A173 | T8: 2 | U8: A191 | V8: A201 | W8: 1
B9: 5 | C9: A11 | D9: 24 | E9: A33 | F9: A40 | G9: 4870 | H9: A61 | I9: A73 | J9: 3 | K9: A93 | L9: A101 | M9: 4 | N9: A124 | O9: 53 | P9: A143 | Q9: A153 | R9: 2 | S9: A173 | T9: 2 | U9: A191 | V9: A201 | W9: 2
B10: 6 | C10: A14 | D10: 36 | E10: A32 | F10: A46 | G10: 9055 | H10: A65 | I10: A73 | J10: 2 | K10: A93 | L10: A101 | M10: 4 | N10: A124 | O10: 35 | P10: A143 | Q10: A153 | R10: 1 | S10: A172 | T10: 2 | U10: A192 | V10: A201 | W10: 1
B11: 7 | C11: A14 | D11: 24 | E11: A32 | F11: A42 | G11: 2835 | H11: A63 | I11: A75 | J11: 3 | K11: A93 | L11: A101 | M11: 4 | N11: A122 | O11: 53 | P11: A143 | Q11: A152 | R11: 1 | S11: A173 | T11: 1 | U11: A191 | V11: A201 | W11: 1
B12: 8 | C12: A12 | D12: 36 | E12: A32 | F12: A41 | G12: 6948 | H12: A61 | I12: A73 | J12: 2 | K12: A93 | L12: A101 | M12: 2 | N12: A123 | O12: 35 | P12: A143 | Q12: A151 | R12: 1 | S12: A174 | T12: 1 | U12: A192 | V12: A201 | W12: 1
B13: 9 | C13: A14 | D13: 12 | E13: A32 | F13: A43 | G13: 3059 | H13: A64 | I13: A74 | J13: 2 | K13: A91 | L13: A101 | M13: 4 | N13: A121 | O13: 61 | P13: A143 | Q13: A152 | R13: 1 | S13: A172 | T13: 1 | U13: A191 | V13: A201 | W13: 1
B14: 10 | C14: A12 | D14: 30 | E14: A34 | F14: A40 | G14: 5234 | H14: A61 | I14: A71 | J14: 4 | K14: A94 | L14: A101 | M14: 2 | N14: A123 | O14: 28 | P14: A143 | Q14: A152 | R14: 2 | S14: A174 | T14: 1 | U14: A191 | V14: A201 | W14: 2
B15: 11 | C15: A12 | D15: 12 | E15: A32 | F15: A40 | G15: 1295 | H15: A61 | I15: A72 | J15: 3 | K15: A92 | L15: A101 | M15: 1 | N15: A123 | O15: 25 | P15: A143 | Q15: A151 | R15: 1 | S15: A173 | T15: 1 | U15: A191 | V15: A201 | W15: 2
B16: 12 | C16: A11 | D16: 48 | E16: A32 | F16: A49 | G16: 4308 | H16: A61 | I16: A72 | J16: 3 | K16: A92 | L16: A101 | M16: 4 | N16: A122 | O16: 24 | P16: A143 | Q16: A151 | R16: 1 | S16: A173 | T16: 1 | U16: A191 | V16: A201 | W16: 2
... B1004: 1000 | C1004: A12 | D1004: 45 | E1004: A34 | F1004: A41 | G1004: 4576 | H1004: A62 | I1004: A71 | J1004: 3 | K1004: A93 | L1004: A101 | M1004: 4 | N1004: A123 | O1004: 27 | P1004: A143 | Q1004: A152 | R1004: 1 | S1004: A173 | T1004: 1 | U1004: A191 | V1004: A201 | W1004: 1

Sheet Codebook
B2: Codebook
B3: Purpose: meaning of every variable and code.
B5: Variable | C5: Type | D5: Code | E5: Meaning
B6: applicant_id | C6: identifier | E6: Row number added for reference
B7: checking_status | C7: categorical | D7: A11 | E7: < 0 DM
B8: checking_status | C8: categorical | D8: A12 | E8: 0 to < 200 DM
B9: checking_status | C9: categorical | D9: A13 | E9: >= 200 DM or salary assignment
B10: checking_status | C10: categorical | D10: A14 | E10: no checking account
B11: duration_months | C11: numeric | E11: Loan duration in months
B12: credit_history | C12: categorical | D12: A30 | E12: no credits taken / all paid back duly
B13: credit_history | C13: categorical | D13: A31 | E13: all credits at this bank paid back duly
B14: credit_history | C14: categorical | D14: A32 | E14: existing credits paid back duly till now
B15: credit_history | C15: categorical | D15: A33 | E15: delay in paying off in the past
B16: credit_history | C16: categorical | D16: A34 | E16: critical account / other credits elsewhere
B17: purpose | C17: categorical | D17: A40 | E17: car (new)
B18: purpose | C18: categorical | D18: A41 | E18: car (used)
B19: purpose | C19: categorical | D19: A42 | E19: furniture/equipment
B20: purpose | C20: categorical | D20: A43 | E20: radio/television
B21: purpose | C21: categorical | D21: A44 | E21: domestic appliances
B22: purpose | C22: categorical | D22: A45 | E22: repairs
B23: purpose | C23: categorical | D23: A46 | E23: education
... B27: purpose | C27: categorical | D27: A410 | E27: others
B28: credit_amount | C28: numeric | E28: Loan amount (Deutsche Mark)
B29: savings | C29: categorical | D29: A61 | E29: < 100 DM
B30: savings | C30: categorical | D30: A62 | E30: 100 to < 500 DM
B31: savings | C31: categorical | D31: A63 | E31: 500 to < 1000 DM
B32: savings | C32: categorical | D32: A64 | E32: >= 1000 DM
B33: savings | C33: categorical | D33: A65 | E33: unknown / no savings account
B34: employment_since | C34: categorical | D34: A71 | E34: unemployed
B35: employment_since | C35: categorical | D35: A72 | E35: < 1 year
B36: employment_since | C36: categorical | D36: A73 | E36: 1 to < 4 years
B37: employment_since | C37: categorical | D37: A74 | E37: 4 to < 7 years
B38: employment_since | C38: categorical | D38: A75 | E38: >= 7 years
B39: installment_rate_pct | C39: numeric | E39: Installment rate as % of disposable income (1-4, ordinal band)
B40: personal_status_sex | C40: categorical | D40: A91 | E40: male: divorced/separated
B41: personal_status_sex | C41: categorical | D41: A92 | E41: female: divorced/separated/married
B42: personal_status_sex | C42: categorical | D42: A93 | E42: male: single
B43: personal_status_sex | C43: categorical | D43: A94 | E43: male: married/widowed
B44: personal_status_sex | C44: categorical | D44: A95 | E44: female: single
B45: other_debtors | C45: categorical | D45: A101 | E45: none
...
